Workbook

Sheet Info
A1: 📡 Jumbo Shoo Project — LoRa Airtime & Compliance Calculator
A2: User Guide, Purpose & Revision History
A3: This spreadsheet calculates LoRa radio transmission airtime and checks regulatory compliance for the Jumbo Shoo fixed geophone sensor network. Sensor nodes transmit heartbeat, status, and seismic detection event packets to a central brain module (Raspberry Pi) over raw LoRa. The system supports both EU 868 MHz and US 915 MHz frequency bands. Enter your radio parameters and the sheet instantly shows Time on Air (ms), energy consumed per transmission, estimated node battery life, and whether your configuration is within the legal duty cycle (EU) or dwell time (US) limits. Section F provides a dedicated analysis of the detection event channel, showing sensor re-arm time and maximum event rate on g vs g3 sub-bands. This tool is designed for single-sensor configuration and link budget analysis. For multi-sensor array deployments, CAD backoff and channel staggering considerations are documented in the Profiles tab — these are future implementation notes and do not affect single-sensor calculations.
A6: 1. Workbook Structure
A7: Tab | B7: Description
A10: Calculator | B10: Main working sheet. Enter parameters here and read all results. Section F provides independent detection event channel analysis (re-arm time, max event rate). Most users only need this tab.
A11: Presets | B11: Predefined sensor payload profiles (Sensor Heartbeat, Status Report, Detection Event, Alive Ping). Select a preset from the dropdown on the Calculator tab. Edit the Custom row to define your own configuration.
A12: Profiles | B12: Byte-level payload specifications for all four sensor profiles. Field names, sizes, encoding, and notes for each frame type. Includes implementation notes on byte order, timestamp sync, and simultaneous event handling.
A13: Lookup | B13: Reference tables. TX Power → current draw, and EU sub-band duty cycle limits. These tables feed the dropdowns and VLOOKUP formulas on other tabs — do not edit.
A14: References | B14: Technical standards, datasheets, and formula sources used to build this calculator.
A16: 2. Quick Start — 5 Steps
A17: Step 1 — Choose Region | B17: On the Calculator tab, set Region (cell F6) to 1 for EU 868 MHz or 2 for US 915 MHz. This switches the compliance check between EU duty cycle and US dwell time rules.
A18: Step 2 — Select a Preset | B18: Use the Active Preset dropdown (cell C4) to load a predefined sensor profile. Options are tuned for typical Jumbo Shoo packet types. Choose Custom to define your own — edit the Custom row on the Presets tab.
A19: Step 3 — Adjust Parameters | B19: If needed, override individual parameters: Preamble Symbols (C9), CRC (C11), Explicit Header (C12), Supply Voltage (C17), TX Interval (F8), and Battery Capacity (F9) are free-edit inputs. EU Sub-band (F7) selects your operating band and its duty cycle limit.
A20: Step 4 — Read Results | B20: Section C shows Time on Air. Section D shows energy per transmission and estimated battery life (TX-only — add MCU and sensor peripheral current for a full system model). Section E shows compliance status, which turns green (compliant) or red (breach). Section F shows detection event channel analysis: re-arm time and max event rate on g (1%) vs g3 (10%) sub-band side by side.
A21: Step 5 — Iterate | B21: If you see a compliance breach or the battery life is too short, try reducing SF, increasing BW, reducing TX interval, or switching to a sub-band with a higher duty limit (e.g. g3 at 10%).
A23: 3. Parameter Reference
A24: Parameter / Cell | B24: What it means and valid values
A25: Active Preset (C4) | B25: Selects a pre-loaded sensor payload profile that auto-fills SF, BW, CR, Payload, and TX Power. Options: Sensor Heartbeat, Status Report, Detection Event, Alive Ping, Custom.
A26: Spreading Factor (C6) | B26: SF7–SF12. Higher SF = longer range and better sensitivity, but longer airtime and higher energy. SF12 is ~100× slower than SF7. Preset-driven when a profile is selected.
A27: Bandwidth (C7) | B27: 125 / 250 / 500 kHz. Wider bandwidth = shorter airtime but reduced range. US915 commonly uses 500 kHz for uplinks. Preset-driven.
A28: Coding Rate (C8) | B28: Denominator of 4/N: values 5–8. Higher N = more redundancy and error correction, slightly longer airtime. 4/5 is standard. Preset-driven.
A29: Preamble Symbols (C9) | B29: Number of preamble symbols. Default is 8 (LoRaWAN standard). Increase for better sync reliability in noisy environments. Free-edit.
A30: Payload Size (C10) | B30: Bytes of application payload (not including LoRa MAC overhead). Typical values: 8–12 B (ping), 20 B (GPS fix), 42 B (GPS + sensors). Preset-driven.
A31: CRC (C11) | B31: Cyclic Redundancy Check: 1=enabled (recommended), 0=disabled. Adds 2 bytes of error detection. Keep enabled unless you have a specific reason to disable.
A32: Explicit Header (C12) | B32: 1=Explicit (recommended), 0=Implicit. Explicit header carries SF/BW/CR in the packet — required unless all devices are pre-configured identically.
A33: LDRO Required (C13) | B33: Calculated automatically. Low Data Rate Optimization is mandatory when symbol duration > 16 ms (i.e. SF11/12 at 125 kHz). Read-only.
A34: LDRO Manual Override (C14) | B34: Set to 1 to enable LDRO when it is not automatically required (e.g. SF12 at 500 kHz on US915). Has no effect when C13 = 1 (LDRO already forced on). Free-edit: 0 or 1.
A35: TX Power (C16) | B35: Transmit power in dBm. Dropdown sourced from Lookup tab. Select cell to see current draw for each option. EU regulatory limit: 14 dBm EIRP for sub-bands g/g1. RFM95W hardware max: 20 dBm (PA_BOOST, 1% duty cycle limit at that level). Continuous operation: 17 dBm. Preset-driven, EU/US auto-selected.
... A40: Battery Capacity (F9) | B40: Total battery capacity in mAh. Used to estimate battery life based on TX-only current draw. Note: add idle current, MCU, and GPS fix power for a full system model. Free-edit.
A42: 4. Color Coding Guide
A43: Blue bold text, white cell | B43: Editable input — you can and should change these values.
A44: Orange bold text, amber cell | B44: Preset-driven input — value comes from the selected preset. Change via Active Preset dropdown, or choose Custom.
A45: Black text, light gray cell | B45: Calculated value — do not edit. Derived from your inputs using the LoRa airtime formula.
A46: White text, dark green header | B46: Section header — organises the sheet into logical groups.
A47: White text, dark green cell | B47: Compliant result — your configuration is within the regulatory limit.
A48: White text, deep red cell | B48: Breach — configuration exceeds the regulatory limit. Adjust SF, BW, payload, TX interval, or sub-band.
A49: Gray text, gray cell | B49: Inactive field — not applicable for the current region. EU Sub-band is grayed out when Region = US.
A51: 5. Regulatory Compliance Summary
A52: EU 868 MHz — Duty Cycle | B52: Under ETSI EN 300 220, transmitters must not exceed a defined duty cycle within any 1-hour window. The limit depends on sub-band: g and g1 = 1%, g2 = 0.1% (very restrictive — avoid for frequent sensor TX), g3 = 10% (recommended for detection event channels). The calculator shows the percentage of the limit consumed at your chosen TX interval and flags a breach if you exceed it.
...

Sheet Calculator
A1: 📡 Jumbo Shoo Project — LoRa Airtime & Compliance Calculator
A3: Semtech AN1200.13 · EU ETSI EN 300 220 · US FCC §15.247 | Blue = manual inputs · Orange = preset-driven (change via Active Preset selector) · Black = calculated | ⚠ Single-sensor model — see Profiles tab for multi-sensor array notes
B4: Active Preset | C4: Sensor Heartbeat | E4: =IFERROR(INDEX(Presets!C7:C11,MATCH(C4,Presets!B7:B11,0)),"— select a preset —") -> Node alive + battery voltage + temperature
B5: A. LoRa Radio Parameters | E5: B. Transmission Settings
B6: Spreading Factor [preset] | C6: =IFERROR(INDEX(Presets!D7:D11,MATCH($C$4,Presets!$B$7:$B$11,0)),"") -> 12 | E6: Region (EU=1, US=2) | F6: 1
B7: Bandwidth (kHz) [preset] | C7: =IFERROR(INDEX(Presets!E7:E11,MATCH($C$4,Presets!$B$7:$B$11,0)),"") -> 125 | E7: EU Sub-band (EU only) | F7: g
B8: Coding Rate (4/N) [preset] | C8: =IFERROR(INDEX(Presets!F7:F11,MATCH($C$4,Presets!$B$7:$B$11,0)),"") -> 6 | E8: TX Interval (minutes) | F8: 15
B9: Preamble Symbols | C9: 8 | E9: Battery Capacity (mAh) | F9: 2000
B10: Payload Size (bytes) [preset] | C10: =IFERROR(INDEX(Presets!G7:G11,MATCH($C$4,Presets!$B$7:$B$11,0)),"") -> 12 | E10: Region Label | F10: =IF(F6=1,"EU 868 MHz","US 915 MHz") -> EU 868 MHz
B11: CRC Enabled? (1=yes, 0=no) | C11: 1
B12: Explicit Header? (1=yes, 0=no) | C12: 1
B13: LDRO Required? (Tsym > 16 ms) | C13: =IF((2^C6/(C7*1000))*1000>16,1,0) -> 1
B14: LDRO Manual Override (0=off, 1=on) | C14: 0
B15: LDRO Active (used in calc) | C15: =IF(C13=1,1,C14) -> 1
B16: TX Power (dBm) [preset, EU/US auto] | C16: =IFERROR(IF($F$6=1,INDEX(Presets!$H$7:$H$11,MATCH($C$4,Presets!$B$7:$B$11,0)),INDEX(Presets!$I$7:$I$11,MATCH($C$4,Presets!$B$7:$B$11,0))),14) -> 14
B17: Supply Voltage (V) | C17: 3.7
B18: TX Current (mA) [from Lookup] | C18: =IFERROR(VLOOKUP(C16,Lookup!B:C,2,0),31) -> 31
B20: C. Calculated Results
B21: Symbol Duration (ms) | C21: =(2^C6/C7/1000)*1000 -> 32.768 | E21: Preamble Duration (ms) | F21: =(C9+4.25)*C21 -> 401.408
B22: Payload Symbols (n) | C22: =8+MAX(CEILING((8*C10-4*C6+28+16*C11-20*IF(C6=6,1,(1-C12)))/(4*(C6-2*C15)),1)*(C8-4+4),0) -> 26 | E22: Payload Duration (ms) | F22: =C22*C21 -> 851.968
B24: ⏱ TIME ON AIR (ms) | E24: =F21+F22 -> 1253.376
B25: Effective Bitrate (kbps) | C25: =C6*(4/(4+(C8-4)))*C7*1000/2^C6/1000 -> 0.24414062 | E25: Symbol Duration (Tsym ms) | F25: =C21 -> 32.768
B27: D. Energy per Transmission
B28: Energy per TX (mJ) | C28: =C18/1000*C17*(E24/1000)*1000 -> 143.76223 | E28: Charge per TX (µAh) | F28: =C18*(E24/1000)/3.6 -> 10.79296
B29: TX per hour | C29: =60/F8 -> 4 | E29: TX per day | F29: =C29*24 -> 96
B30: TX mAh consumed / day | C30: =(F28/1000)*F29 -> 1.0361242 | E30: Battery Life — TX only (years) | F30: =IF(C30>0,F9/C30/365,9999) -> 5.2884126
B32: E. Regulatory Compliance (EU: duty cycle · US: dwell time)
B33: Duty cycle used per TX (EU) | C33: =IF(F6=1,(E24/3600000)*100,"") -> 0.034816 | E33: Duty cycle used per hour (EU) | F33: =IF(F6=1,C33*C29,"") -> 0.139264
B34: % of EU duty budget consumed | C34: =IF(F6=1,F33/(IFERROR(VLOOKUP($F$7,Lookup!$B$19:$E$22,4,0),1))*100,"") -> 13.9264 | E34: Max TX/hr (EU duty limit) | F34: =IF(F6=1,INT((IFERROR(VLOOKUP($F$7,Lookup!$B$19:$E$22,4,0),1)/100*3600000)/E24),"") -> 28
B35: Min TX interval — EU (seconds) | C35: =IF(F6=1,E24/((IFERROR(VLOOKUP($F$7,Lookup!$B$19:$E$22,4,0),1))/100)/1000,"") -> 125.3376 | E35: US Dwell Time OK? (≤400 ms) | F35: =IF(F6=2,IF(E24<=400,"✓ COMPLIANT","✗ EXCEEDS 400 ms LIMIT"),"")
B37: Compliance Status | E37: =IF(F6=1,IF(F33<=IFERROR(VLOOKUP($F$7,Lookup!$B$19:$E$22,4,0),1),"✓ EU COMPLIANT","✗ EU DUTY CYCLE BREACH — reduce TX rate or switch sub-band"),IF(E24<=400,"✓ US COMPLIANT","✗ US DWELL BREACH — reduce SF or increase BW")) -> ✓ EU COMPLIANT
B39: Note: Battery life is TX-only. Add idle/sleep current, MCU draw, and any peripheral power for a full system model. TX current figures are SX1262/SX1276 typical values.
B41: F. Sensor Re-arm Reference (EU only — driven by current ToA)
B42: Select the Detection Event preset to see re-arm time for that payload. Values are always live — driven by the current ToA. g3 (10% duty) is recommended for the EU detection event channel.
B43: Metric | C43: g / g1 (1% duty) | E43: g3 (10% duty) | F43: Improvement
B44: Min re-arm per sensor (s) | C44: =E24/0.01/1000 -> 125.3376 | E44: =E24/0.1/1000 -> 12.53376 | F44: =TEXT(C44/E44,"0.0")&"×" -> 10.0×
B45: Max detection events / hr | C45: =INT(3600/C44) -> 28 | E45: =INT(3600/E44) -> 287 | F45: =TEXT(E45/C45,"0.0")&"×" -> 10.3×
B46: EU only. g3 (869.4–869.65 MHz, 10% duty) max BW = 125 kHz. For US 915 there is no duty cycle limit — dwell time rule (≤400 ms) applies instead.
B48: G. Configuration Warnings
B49: BW + Sub-band (EU) | C49: =IF(NOT(AND($F$6=1,$C$7=500,$F$7="g3")),"✓ OK — BW valid for selected sub-band",IF(AND($F$6=1,$C$7=500,$F$7="g3"),"✗ VIOLATION: BW500 cannot fit in g3 (250 kHz slice). Use BW125 or switch sub-band.","")) -> ✓ OK — BW valid for selected sub-band
...

Sheet Presets
A1: 📡 Jumbo Shoo Project — Sensor Payload Profiles
A3: Reference profiles for Jumbo Shoo fixed geophone sensor nodes. Select a preset on the Calculator tab to auto-fill SF / BW / CR / Payload / TX Power.
B5: A. Sensor Payload Profiles
B6: Profile | C6: Description | D6: SF | E6: BW (kHz) | F6: CR (N) | G6: Payload (B) | H6: TX Pwr EU | I6: TX Pwr US | J6: Region | K6: Notes
B7: Sensor Heartbeat | C7: Node alive + battery voltage + temperature | D7: 12 | E7: 125 | F7: 6 | G7: 12 | H7: 14 | I7: 20 | J7: Both | K7: Standard interval heartbeat
B8: Status Report | C8: RPi diagnostics + sensor health metrics | D8: 12 | E8: 125 | F8: 6 | G8: 24 | H8: 14 | I8: 20 | J8: Both | K8: Periodic full status burst
B9: Detection Event | C9: Seismic trigger: node ID + timestamp + amplitude | D9: 12 | E9: 125 | F9: 6 | G9: 8 | H9: 14 | I9: 20 | J9: Both | K9: Low-latency, min payload
B10: Alive Ping | C10: Minimal keepalive, low power | D10: 12 | E10: 125 | F10: 6 | G10: 6 | H10: 14 | I10: 20 | J10: Both | K10: Min power, min airtime
B11: Custom | C11: Edit values below — used when Custom selected on Calculator | D11: 12 | E11: 125 | F11: 6 | G11: 12 | H11: 14 | I11: 20 | J11: Both | K11: Freely editable
B12: ⬆ When 'Custom' is selected on the Calculator tab, the SF / BW / CR / Payload / TX Power values above are used. Edit the blue cells to change them.

Sheet Profiles
A1: 📡 Jumbo Shoo Project — Sensor Payload Profile Specifications
A2: Byte-level payload definitions for each preset. All profiles use explicit header and CRC enabled. Packet type byte routes frames at the brain module.
A4: Sensor Heartbeat — Node alive · battery voltage · temperature
A5: SF8 · BW 125 kHz · CR 4/5 · 12 bytes · EU 14 dBm / US 20 dBm · LDRO off (Tsym 1.024 ms)
A6: Transmitted on a fixed interval (default 15 min). Confirms the sensor node is alive and provides essential health metrics. SF8 gives adequate link margin for fixed outdoor deployments without the current penalty of SF9+. Low payload keeps airtime short (~110 ms).
B7: Field | C7: Size | E7: Encoding | F7: Notes
B8: Node ID | C8: 1 B | E8: uint8 — node address 0–254 (255 = broadcast) | F8: Assigned at deployment
B9: Packet Type | C9: 1 B | E9: uint8 — 0x01 = Heartbeat | F9: Routes frame at brain module
B10: Timestamp | C10: 4 B | E10: uint32 LE — Unix epoch seconds | F10: Brain module clock or sync reference
B11: Battery Voltage | C11: 2 B | E11: uint16 LE — millivolts (3700 = 3.700 V) | F11: ADC reading pre-TX
B12: Temperature | C12: 2 B | E12: int16 LE — 0.01 °C (2350 = 23.50 °C) | F12: DS18B20 or NTC onboard sensor
B13: Sequence No. | C13: 2 B | E13: uint16 LE — rolls over at 65535 | F13: Detects missed packets at brain
A14: Total Payload: 12 bytes
A16: Status Report — RPi diagnostics · sensor health metrics
A17: SF8 · BW 125 kHz · CR 4/5 · 24 bytes · EU 14 dBm / US 20 dBm · LDRO off (Tsym 1.024 ms)
A18: Transmitted less frequently than heartbeat (suggested every 1–4 hr). Provides a full diagnostic snapshot of the Raspberry Pi brain module and geophone sensor health. Enables remote monitoring without physical access. Airtime ~150 ms at SF8/125 kHz.
B19: Field | C19: Size | E19: Encoding | F19: Notes
B20: Node ID | C20: 1 B | E20: uint8 — node address
B21: Packet Type | C21: 1 B | E21: uint8 — 0x02 = Status Report
B22: Timestamp | C22: 4 B | E22: uint32 LE — Unix epoch seconds
B23: Battery Voltage | C23: 2 B | E23: uint16 LE — millivolts | F23: Same encoding as Heartbeat
B24: RPi CPU Temp | C24: 1 B | E24: uint8 — °C integer (saturates at 127) | F24: vcgencmd measure_temp
B25: RPi CPU Load | C25: 1 B | E25: uint8 — 1-min load avg × 100, capped at 255 | F25: From /proc/loadavg
B26: RPi Free RAM | C26: 2 B | E26: uint16 LE — MB free (from /proc/meminfo)
B27: Geophone Status | C27: 1 B | E27: Bitmask: bit0=active, bit1=fault, bit2=thresh | F27: 0x01 = normal operation
B28: Detection Count | C28: 2 B | E28: uint16 LE — events since last Status Report | F28: Reset to 0 after each TX
B29: Last RSSI | C29: 1 B | E29: int8 — dBm + 200 offset (120 = −80 dBm) | F29: Last downlink received RSSI
B30: Uptime | C30: 4 B | E30: uint32 LE — seconds since last reboot
B31: Firmware Version | C31: 1 B | E31: uint8 — BCD (0x17 = v1.7)
B32: Reserved | C32: 3 B | E32: 0x00 — reserved for future use | F32: Pads frame to 24 bytes
A33: Total Payload: 24 bytes
A35: Detection Event — Seismic trigger · node ID + timestamp + amplitude
A36: SF7 · BW 125 kHz · CR 4/5 · 8 bytes · EU 14 dBm / US 20 dBm · LDRO off (Tsym 0.512 ms)
A37: Transmitted immediately on threshold crossing. SF7 keeps ToA under 40 ms, maximizing sensor re-arm speed. Recommended on EU g3 sub-band (869.4–869.65 MHz, 10% duty) for ~0.36 s re-arm versus ~3.6 s on g/g1. For co-located sensors, assign different sub-channels within g3 to reduce collision probability on simultaneous triggers. SF6 is also supported at this payload size and halves ToA to ~20 ms (g3 re-arm ~196 ms), but requires implicit header mode (SX1276 hardware constraint — explicit header is not supported at SF6). The payload length must be hardcoded in firmware on both sensor and brain. SF6 also uses a different sync word (0x65 vs 0x12) and has ~5 dB less link margin than SF7. Only suitable for fixed-length payloads in short-range deployments.
B38: Field | C38: Size | E38: Encoding | F38: Notes
B39: Node ID | C39: 1 B | E39: uint8 — node address
B40: Packet Type | C40: 1 B | E40: uint8 — 0x03 = Detection Event
B41: Timestamp | C41: 4 B | E41: uint32 LE — ms offset from shared epoch reference | F41: Sub-second precision for TOA localization
B42: Peak Amplitude | C42: 1 B | E42: uint8 — normalized 0–255 (255 = full ADC scale) | F42: Calibrated per deployment
B43: Event Flags | C43: 1 B | E43: bits 0-1: duration class bits 2-3: SNR class bit 4: secondary peak | F43: 00=<100ms 01=<500ms 10=<2s 11=>2s
...

Sheet Lookup
A1: 📡 Jumbo Shoo Project — Reference Lookup Tables
A3: TX Power table → Calculator!C18 · Sub-band table → Calculator!F7 · Label column (E) → dropdown source on Presets TX Power fields
B5: A. TX Power / Current Reference (RFM95W — HopeRF, Table 5)
B6: TX Power (dBm) | C6: Current (mA) | D6: Notes | E6: Dropdown Label
B7: 2 | C7: 13 | D7: RFO_HF path. Linear interpolation from Table 5 anchors (7 dBm/20 mA, 13 dBm/29 mA), slope 1.5 mA/dBm. No direct datasheet measurement at this level. Rarely used in practice. | E7: 2 dBm | 13 mA [est.]
B8: 5 | C8: 17 | D8: RFO_HF path. Linear interpolation from Table 5 anchors (7 dBm/20 mA, 13 dBm/29 mA), slope 1.5 mA/dBm. No direct datasheet measurement at this level. | E8: 5 dBm | 17 mA [est.]
B9: 8 | C9: 22 | D9: RFO_HF path. Linear interpolation from Table 5 anchors (7 dBm/20 mA, 13 dBm/29 mA), slope 1.5 mA/dBm. Direct measurement at 7 dBm adjacent — estimate reliable to ±2 mA. | E9: 8 dBm | 22 mA [est.]
B10: 11 | C10: 26 | D10: RFO_HF path. Linear interpolation from Table 5 anchors (7 dBm/20 mA, 13 dBm/29 mA), slope 1.5 mA/dBm. Direct measurement at 13 dBm adjacent — estimate reliable to ±2 mA. | E10: 11 dBm | 26 mA [est.]
B11: 14 | C11: 31 | D11: RFO_HF path. Linear extrapolation from Table 5 anchors (7 dBm/20 mA, 13 dBm/29 mA). PA_HF maximum per §5.4.2 (14 dBm) and Table 31 (15 dBm register ceiling). No Table 5 direct measurement at 14 dBm — estimated ±3 mA. EU EIRP regulatory limit (25 mW). Default EU operating point. | E11: 14 dBm | 31 mA [est.]
B12: 17 | C12: 87 | D12: PA_BOOST path. Direct from datasheet Table 5 (SF12, CR4/6, BW125 kHz, §2.4.5). Firmware must explicitly select PA_BOOST. Rated for continuous operation at this level. | E12: 17 dBm | 87 mA
B13: 20 | C13: 120 | D13: PA_BOOST path. Direct from datasheet Table 5 (SF12, CR4/6, BW125 kHz, §2.4.5). Duty-cycle limited to 1% maximum by hardware (Table 33, DC_20dBm parameter). Not rated for continuous operation. | E13: 20 dBm | 120 mA
B14: PA Path Architecture (RFM95W / SX1276, HF band 862–1020 MHz) RFO_HF path (rows above, 2–14 dBm): standard output amplifier. §5.4.2 gives 14 dBm as the recommended max; Table 31 (RegPaConfig) lists 15 dBm as the register ceiling. Two Table 5 direct measurements: 7 dBm/20 mA and 13 dBm/29 mA. All other RFO_HF values are linear interpolations (slope 1.5 mA/dBm) — labelled [est.] in the dropdown. Accuracy ±2–3 mA within the 7–13 dBm range; lower confidence outside it. PA_BOOST path (rows below, 17–20 dBm): high-power amplifier, selected explicitly by firmware. Two Table 5 direct measurements: 17 dBm/87 mA and 20 dBm/120 mA. The gap 15–16 dBm is a PA path transition zone — current draw is indeterminate and these levels are omitted from the dropdown. Do not interpolate across the 14→17 dBm boundary.
B17: B. EU 868 MHz Sub-Band Reference (ETSI EN 300 220)
B18: Sub-band | C18: Frequencies | D18: Duty Cycle | E18: Duty % (numeric) | G18: Notes / Recommendation
B19: g | C19: 868.0–868.6 MHz | D19: 1% | E19: 1 | G19: General purpose — default LoRaWAN uplink
B20: g1 | C20: 863.0–868.0 MHz | D20: 1% | E20: 1 | G20: Lower EU band
B21: g2 | C21: 868.7–869.2 MHz | D21: 0.1% | E21: 0.1 | G21: Very restricted — avoid for frequent sensor TX
B22: g3 | C22: 869.4–869.65 MHz | D22: 10% | E22: 10 | G22: Best choice for high-frequency tracking

Sheet References
A1: 📡 Jumbo Shoo Project — Technical References & Sources
A2: Standards, datasheets, and technical documents used to build this calculator.
A4: A. Core Airtime Formula
A5: Document | B5: Reference / Version | C5: Relevance to this calculator
A6: Semtech AN1200.13 — LoRa Modem Designer's Guide | B6: Rev 1, July 2013 | C6: Primary source for the Time on Air formula: preamble duration, payload symbol count, LDRO activation threshold (Tsym > 16 ms), and coding rate overhead. All airtime cells in Section C derive from this document.
A7: SX1272/73 — 860 MHz to 1020 MHz Low Power Long Range Transceiver | B7: Semtech Datasheet Rev 4, March 2019 | C7: Original transceiver spec confirming formula constants and LDRO requirement. TX current values for 2–17 dBm range sourced from Table 11.
A8: SX1261/2 — Sub-GHz Long Range Transceiver | B8: Semtech Datasheet Rev 2.1, 2020 | C8: Referenced for high-power PA data (22–23 dBm). Note: these power levels are NOT achievable on the RFM95W (max +20 dBm). This entry is retained for reference only. For actual hardware current draw, see Section E (RFM95W datasheet).
A10: B. EU Regulatory Standards
A11: Document | B11: Reference / Version | C11: Relevance to this calculator
A12: ETSI EN 300 220-1 — Short Range Devices (SRD) | B12: V3.1.1 (2017-02) | C12: Defines the EU 868 MHz SRD band plan, sub-band allocations (g, g1, g2, g3), and the per-sub-band duty cycle limits used in the Lookup tab band table.
A13: ETSI EN 300 220-2 — SRD Technical Characteristics | B13: V3.2.1 (2018-06) | C13: Specifies maximum EIRP: 25 mW (14 dBm) for most sub-bands. Informs the EU TX power default and the EU max warning on the Presets tab.
A14: LoRa Alliance — LoRaWAN Regional Parameters | B14: RP002-1.0.4 (2021) | C14: Defines EU868 channel plan, default channels, and recommended TX power levels. Confirms g sub-band as the primary LoRaWAN uplink band.
A16: C. US Regulatory Standards
A17: Document | B17: Reference / Version | C17: Relevance to this calculator
A18: FCC §15.247 — Operation within the bands 902–928 MHz | B18: 47 CFR Part 15, current | C18: Governs US 915 MHz FHSS operation. Requires ≥50 channels, maximum 400 ms dwell time per channel per transmission. No fixed duty cycle. The 400 ms dwell time check in Section E derives from this rule.
A19: FCC §15.209 — Radiated emission limits | B19: 47 CFR Part 15, current | C19: Sets conducted and radiated power limits. Max 30 dBm EIRP for §15.247 FHSS in the 902–928 MHz band. In practice SX1262 hardware limits to 23 dBm.
A20: LoRa Alliance — LoRaWAN Regional Parameters (US915) | B20: RP002-1.0.4 (2021) | C20: Defines US915 channel plan: 64 uplink channels at 125 kHz BW and 8 at 500 kHz BW. SF7–SF10 at 125 kHz, SF8 at 500 kHz for uplinks. Used to validate preset configurations.
A22: D. Notes & Assumptions
A24: Note 1 | B24: TX current values are typical figures from Semtech datasheets and will vary with supply voltage, temperature, and PCB design. Measure on your actual hardware for a precise battery model.
A25: Note 2 | B25: Battery life estimate is TX-only. A realistic system model must add: idle/sleep current (typically 1–10 µA for the LoRa module), MCU/RPi current, and any active sensor peripheral draw. Measure on your actual hardware configuration for accuracy.
A26: Note 3 | B26: The LDRO Tsym > 16 ms threshold is from AN1200.13 §4. The original heuristic of 'SF11/12 at 125 kHz' is a common approximation that misses SF12 at 500 kHz (Tsym ≈ 8 ms) — this calculator uses the exact threshold.
A27: Note 4 | B27: Duty cycle is calculated over a rolling 1-hour window as required by ETSI EN 300 220. The formula is: duty% = (ToA_ms / 3,600,000) × 100 × (transmissions per hour).
A28: Note 5 | B28: This calculator models raw LoRa airtime. The Jumbo Shoo system operates point-to-point (sensor node → brain module) without a LoRaWAN network stack, so LoRaWAN MAC overhead (13 B OTAA / 8 B ABP) does not apply. If a LoRaWAN gateway is added later, add MAC overhead to the Payload Size input.
A30: E. Hardware Reference — Actual Transceiver Module
A31: Document | B31: Reference / Version | C31: Relevance to this calculator
A32: RFM95W/96W/98W — Low Power Long Range Transceiver Module | B32: HopeRF Datasheet v2.0 (hoperf.com) | C32: Actual transceiver module used in Jumbo Shoo sensor nodes. Based on Semtech SX1276 silicon. TX current values in Lookup tab Section A are derived as follows: (1) Direct Table 5 measurements at four points — 7 dBm/20 mA and 13 dBm/29 mA (RFO_HF path) and 17 dBm/87 mA and 20 dBm/120 mA (PA_BOOST path) — test conditions §2.4.5: SF12, CR4/6, BW125 kHz. (2) RFO_HF intermediate values (2, 5, 8, 11, 14 dBm) are linearly interpolated/extrapolated from the 7 and 13 dBm anchors at slope 1.5 mA/dBm; marked [est.] in dropdown labels. PA_HF maximum: 14 dBm per §5.4.2 text (15 dBm per Table 31 register ceiling). (3) The 15–16 dBm range spans a PA path switch (RFO_HF → PA_BOOST) and is omitted — current draw is indeterminate in this zone. Max TX power 20 dBm (PA_BOOST), duty-cycle limited to 1% per Table 33 (DC_20dBm). Continuous operation rated to 17 dBm. Preset defaults based on §2.4.5 test conditions (SF12, CR4/6, BW125, preamble 8, CRC on).
A34: F. Academic References — Multi-Sensor MAC & Collision Avoidance
A35: Document | B35: Reference / Version | C35: Relevance to this project
A36: A Slotted Transmission with Collision Avoidance for LoRa Networks | B36: Hoang, Q.L., Tran, H.P., Jung, W.S., Hoang, S.H., Oh, H. Procedia Computer Science 177 (2020) 94–101 EUSPN 2020, Madeira, Portugal DOI: 10.1016/j.procs.2020.10.016 Open access CC BY-NC-ND 4.0 | C36: Introduces the ST/CA protocol: slotted transmission + LBT with Channel Activity Detection (CAD) backoff for collision avoidance in LoRa networks. Directly relevant to Jumbo Shoo multi-sensor array deployments where simultaneous seismic detection events cause co-located sensors to transmit concurrently. Table 1 (p.99) provides CAD timing values for SF7–12 at BW125/CR4:5 used in the CAD backoff algorithm documented in the Profiles tab. Key finding: at SF7 with MaxDelayCnt=6, max random delay (11.82 ms) fits within the preamble window (12.54 ms), ensuring a deferred node correctly detects a winning node's transmission via CAD. Note: current Jumbo Shoo tool models single-sensor configurations only. Multi-sensor MAC is a future consideration — see Profiles tab for implementation notes.
